<?xml version="1.0"?>

<robot xmlns:xacro="http://www.ros.org/wiki/xacro" 
 	xmlns:sensor="http://playerstage.sourceforge.net/gazebo/xmlschema/#sensor"
    	xmlns:controller="http://playerstage.sourceforge.net/gazebo/xmlschema/#controller"
    	xmlns:interface="http://playerstage.sourceforge.net/gazebo/xmlschema/#interface"
	name="charle_xacro">

	<xacro:include filename="$(find charle_description)/urdf/charle.gazebo" />


	<xacro:property name="length_thruster" value="0.2" />
	<xacro:property name="radius_thruster" value="0.01" />
	<xacro:macro name="default_inertial" params="mass">
               <inertial>
                       <mass value="${mass}" />
                       <inertia ixx="1" ixy="0.0" ixz="0.0"
                                iyy="1" iyz="0.0"
                                izz="0.01" />
               </inertial>
	</xacro:macro>

	<link name="base_footprint">
   		<visual>
			<geometry>
      				<box size="0.001 0.001 0.001"/>
     			</geometry>
			<origin rpy="0 0 0" xyz="0 0 0"/>
   		</visual>
			<collision>
				<geometry>
	       				<box size="0.2 .3 0.1"/>
				</geometry>
			</collision>
		<xacro:default_inertial mass="0.0001"/>
 	</link>

	<gazebo reference="base_footprint">
		<material>Gazebo/Green</material>
		<turnGravityOff>false</turnGravityOff>
	</gazebo>

	<joint name="base_footprint_joint" type="fixed">
		<origin xyz="0 0 0" />
		<parent link="base_footprint" />
		<child link="base_link" />
	</joint>

  <link name="base_link">
    <visual>
	<origin rpy="1.57 0 0" xyz="0 0 0" />
      <geometry>
        <mesh filename="package://charle_description/urdf/AVORA_body_stl.STL" scale="0.001 0.001 0.001"/>
      </geometry>
      <material name="blue">
     	<color rgba="0 0 .8 1"/>
      </material>
    </visual>
	 <collision>
			<geometry>
       				<box size="0.2 .3 0.1"/>
			</geometry>
	 </collision>
	 <xacro:default_inertial mass="0.5"/>
  </link>


 	<joint name="base_to_thruster_1" type="continuous">
   	<parent link="base_link"/>
   	<child link="thruster_1"/>
   	<origin rpy="0 1.5707 0" xyz="0.0 0.25 0"/>
   	<axis xyz="0 0 1" />
 	</joint>

 	<link name="thruster_1">
   		<visual>
     			<geometry>
       				<cylinder length="${length_thruster}" radius="${radius_thruster}"/>
     			</geometry>
			<!-- <origin rpy="0 1.5 0" xyz="0.1 0.1 0"/> -->
			<origin rpy="0 0 0" xyz="0 0 0"/>
		</visual>
		<collision>
			<geometry>
       				<cylinder length="${length_thruster}" radius="${radius_thruster}"/>
			</geometry>
		</collision>
		<xacro:default_inertial mass="0.5"/>
 	</link>


 <joint name="base_to_thruster_2" type="continuous">
   <parent link="base_link"/>
   <child link="thruster_2"/>
   <origin rpy="0 1.5707 0" xyz="0.0 -0.25 0"/>
   <axis xyz="0 0 1" />
 </joint>


 	<link name="thruster_2">
   		<visual>
     			<geometry>
       				<cylinder length="${length_thruster}" radius="${radius_thruster}"/>
     			</geometry>
			<!-- <origin rpy="0 1.5 0" xyz="0.1 0.1 0"/> -->
			<origin rpy="0 0 0" xyz="0 0 0"/>
		</visual>
		<collision>
			<geometry>
       				<cylinder length="${length_thruster}" radius="${radius_thruster}"/>
			</geometry>
		</collision>
		<xacro:default_inertial mass="0.5"/>
 	</link>


  <joint name="sonar_to_base_link" type="revolute">
    <parent link="base_link"/>
    <child link="sonar"/>
    <origin rpy="1.5707 0 0" xyz="-0.0 -0 -0.205"/>
    <axis xyz="1 0 0" />
    <limit effort ="1000.0" lower="-1.57" upper="1.57" velocity="0.5"/>
  </joint>

  <link name="sonar">
    <visual>
	<origin rpy="0 0 0" xyz="0 0.0 -0.0" />
      <geometry>
        <mesh filename="package://charle_description/urdf/AVORA_sonar_stl.STL" scale="0.001 0.001 0.001"/>
      </geometry>
      <material name="blue">
     	<color rgba="0 0 .8 1"/>
      </material>
    </visual>
	 <collision>
			<geometry>
       				<cylinder length="0.01" radius="0.03"/>
			</geometry>
 	 </collision>
      <xacro:default_inertial mass="0.5"/>

  </link>


  <joint name="sonarDato_to_sonar" type="fixed">
    <parent link="sonar"/>
    <child link="sonarDato"/>
    <origin rpy="1.57 0 0" xyz="-0.0 -0.075 -0.02"/>
  </joint>

  <link name="sonarDato">
    <visual>
	<origin rpy="0 0 0" xyz="-0.0 -0.0 0.0"/>
      <geometry>
        <cylinder length="0.02" radius="0.02"/>	
      </geometry>
      <material name="blue">
     	<color rgba="0 0 .8 1"/>
      </material>
    </visual>
  </link>


  <joint name="laserDato_to_sonar" type="fixed">
    <parent link="sonar"/>
    <child link="laserDato"/>
    <origin rpy="1.57 3.14 3.14" xyz="-0.0 -0.075 -0.02"/>
  </joint>

  <link name="laserDato">
    <visual>
	<origin rpy="0 0 0" xyz="-0.0 -0.0 0.0"/>
      <geometry>
        <cylinder length="0.02" radius="0.02"/>	
      </geometry>
      <material name="blue">
     	<color rgba="0 0 .8 1"/>
      </material>
    </visual>
  </link>


  <joint name="servo_head_to_base_link" type="revolute">
    <parent link="base_link"/>
    <child link="servo_head"/>
    <origin rpy="0 0.7 3.1414" xyz="0.38 0 0.16"/>
    <axis xyz="0 1 0" />
    <limit effort ="1000.0" lower="-1.5" upper="0.5" velocity="0.5"/>
  </joint>

  <link name="servo_head">
    <visual>
	<origin rpy="1.57 0 0" xyz="0 0 0" />
      <geometry>
        <mesh filename="package://charle_description/urdf/AVORA_servo_head_stl.STL" scale="0.001 0.001 0.001"/>
      </geometry>
      <material name="blue">
     	<color rgba="0 0 .8 1"/>
      </material>
    </visual>
  </link>


  <joint name="head_to_servo_head" type="revolute">
    <parent link="servo_head"/>
    <child link="head"/>
    <origin rpy="0 0 3.14" xyz="0 0 0.04"/>
    <axis xyz="0 0 1" />
    <limit effort ="1000.0" lower="0.8" upper="2.4" velocity="0.5"/>
  </joint>

  <link name="head">
    <visual>
	<origin rpy="1.54 0 -1.54" xyz="0 0 0" />
      <geometry>
        <mesh filename="package://charle_description/urdf/AVORA_head_stl.STL" scale="0.001 0.001 0.001"/>
      </geometry>
      <material name="blue">
     	<color rgba="0 0 .8 1"/>
      </material>
    </visual>
  </link>
</robot>
